<?xml version="1.0"?>
<!-- Revolute-Revolute Manipulator -->
<robot name="robotis_manipulator" xmlns:xacro="http://www.ros.org/wiki/xacro">

  <!-- some parameters -->
  <xacro:property name="pi" value="3.141592654" />

  <!-- Import all Gazebo-customization elements, including Gazebo colors -->
  <xacro:include filename="$(find hcr_description)/urdf/yacra.gazebo" />
  <!-- Import Rviz colors -->
  <xacro:include filename="$(find hcr_description)/urdf/materials.xacro" />

  <link name="link_armBase"/>
  <joint name="joint_armBase" type="fixed">
    <parent link="link_armBase"/>
    <child link="link_arm1"/>
    <origin xyz="0 0 0" rpy="0 0 0"/>
  </joint>

  <!-- link 1 -->
  <link name="link_arm1">
    <collision>
      <origin xyz="-0.0 -0.0666 0" rpy="0 0 0"/>
      <geometry>
        <mesh filename="package://hcr_description/meshes/1.STL" scale="0.001 0.001 0.001"/>
      </geometry>
    </collision>

    <visual>
      <origin xyz="-0.0 -0.0666 0" rpy="0 0 0"/>
      <geometry>
        <mesh filename="package://hcr_description/meshes/1.STL" scale="0.001 0.001 0.001"/>
      </geometry>
      <material name="grey"/>
    </visual>

    <inertial>
      <origin xyz="-0.80 0.00000 -0.8223" rpy="0 0 0"/>
      <!--<origin xyz="0.00023 0.00000 -0.06377" rpy="0 0 0"/>-->
      <!-- <mass value="0.85644"/> -->
      <mass value="0.001"/>
      <inertia ixx="1.0" ixy="0.0" ixz="0.0" iyy="1.0" iyz="0.0" izz="1.0" />
      <!--<inertia ixx="0.00121064" ixy="0.0" ixz="0.00001100" iyy="0.00120886" iyz="0.0" izz="0.00038103" />-->
    </inertial>
  </link>

  <!-- Joint 1 -->
  <joint name="joint_arm1" type="revolute">
    <parent link="link_arm1"/>
    <child link="link_arm2"/>
    <origin xyz="0.0 0.0 0.0" rpy="0 0 0"/>
    <axis xyz="0 0 1"/>
    <limit velocity="6.5" effort="1000" lower="${-pi}" upper="${pi}" />
    <dynamics damping="0.7"/>
  </joint>

  <transmission name="tranmission_arm1">
    <type>transmission_interface/SimpleTransmission</type>
    <joint name="joint_arm1">
      <hardwareInterface>hardware_interface/EffortJointInterface</hardwareInterface>
    </joint>
    <actuator name="actuartor_arm1">
      <hardwareInterface>hardware_interface/EffortJointInterface</hardwareInterface>
      <mechanicalReduction>1</mechanicalReduction>
    </actuator>
  </transmission>

  <!-- link 2 -->
  <link name="link_arm2">
    <collision>
      <origin xyz="-0.015 -0.063 -0.008" rpy="0 0 0"/>
      <geometry>
        <mesh filename="package://hcr_description/meshes/2.STL" scale="0.001 0.001 0.001"/>
      </geometry>
    </collision>

    <visual>
      <origin xyz="-0.015 -0.063 -0.008" rpy="0 0 0"/>
      <geometry>
        <mesh filename="package://hcr_description/meshes/2.STL" scale="0.001 0.001 0.001"/>
      </geometry>
      <material name="grey"/>
    </visual>

    <inertial>
      <origin xyz="0.00000 0.00000 0.00283" rpy="0 0 0"/>
      <!--<origin xyz="0.00000 -0.06820 -0.00117" rpy="0 0 0"/>-->
      <mass value="0.94658"/>
      <!-- <mass value="0.001"/> -->
      <inertia ixx="1.0" ixy="0.0" ixz="0.0" iyy="1.0" iyz="0.0" izz="1.0" />
      <!--<inertia ixx="0.00152547" ixy="0.0" ixz="0.0" iyy="0.00045954" iyz="-0.00001086" izz="0.00151740" />-->
    </inertial>
  </link>

  <!-- Joint 2 -->
  <joint name="joint_arm2" type="revolute">
    <parent link="link_arm2"/>
    <child link="link_arm3"/>
    <origin xyz="-0.01475 -0.01475 0.090" rpy="0 0 0"/>
    <axis xyz="0 1 0"/>
    <limit velocity="6.5" effort="1000" lower="-2.74276" upper="1.76715" />
    <dynamics damping="0.7"/>
  </joint>

  <transmission name="transmission_arm2">
    <type>transmission_interface/SimpleTransmission</type>
    <joint name="joint_arm2">
      <hardwareInterface>hardware_interface/EffortJointInterface</hardwareInterface>
    </joint>
    <actuator name="actuartor_arm2">
      <hardwareInterface>hardware_interface/EffortJointInterface</hardwareInterface>
      <mechanicalReduction>1</mechanicalReduction>
    </actuator>
  </transmission>

  <!-- link 3 -->
  <link name="link_arm3">
    <collision>
      <origin xyz="-0.00006 -0.048 -0.0980" rpy="0 0 0"/>
      <geometry>
        <mesh filename="package://hcr_description/meshes/3.STL" scale="0.001 0.001 0.001"/>
      </geometry>
    </collision>

    <visual>
      <origin xyz="-0.00006 -0.048 -0.0980" rpy="0 0 0"/>
      <geometry>
        <mesh filename="package://hcr_description/meshes/3.STL" scale="0.001 0.001 0.001"/>
      </geometry>
      <material name="grey"/>
    </visual>

    <inertial>
      <origin xyz="0.01768 -0.06881 0.00524" rpy="0 0 0"/>
      <!--<origin xyz="-0.01232 -0.05731 -0.05876" rpy="0 0 0"/>-->
      <mass value="1.30260"/>
      <!-- <mass value="0.001"/> -->
      <inertia ixx="1.0" ixy="0.0" ixz="0.0" iyy="1.0" iyz="0.0" izz="1.0" />
      <!--<inertia ixx="0.01111021" ixy="0.00001331" ixz="-0.00134208" iyy="0.01046642" iyz="0.00016235" izz="0.00202081" />-->
    </inertial>
  </link>

  <!-- Joint 3 -->
  <joint name="joint_arm3" type="revolute">
    <parent link="link_arm3"/>
    <child link="link_arm4"/>
    <origin xyz="0.00000 0.00000 0.1074" rpy="0 0 0"/>
    <axis xyz="0 1 0"/>
    <limit velocity="6.5" effort="1000" lower="-2.83480" upper="2.99433" />
    <dynamics damping="0.7"/>
  </joint>

  <transmission name="transmission_arm3">
    <type>transmission_interface/SimpleTransmission</type>
    <joint name="joint_arm3">
      <hardwareInterface>hardware_interface/EffortJointInterface</hardwareInterface>
    </joint>
    <actuator name="actuartor_arm3">
      <hardwareInterface>hardware_interface/EffortJointInterface</hardwareInterface>
      <mechanicalReduction>1</mechanicalReduction>
    </actuator>
  </transmission>

  <!-- link 4 -->
  <link name="link_arm4">
    <collision>
      <origin xyz="0 -0.048 -0.20569" rpy="0 0 0"/>
      <geometry>
        <mesh filename="package://hcr_description/meshes/4-neu.STL" scale="0.001 0.001 0.001"/>
      </geometry>
    </collision>

    <visual>
      <origin xyz="0 -0.048 -0.20569" rpy="0 0 0"/>
      <geometry>
        <mesh filename="package://hcr_description/meshes/4-neu.STL" scale="0.001 0.001 0.001"/>
      </geometry>
      <material name="grey"/>
    </visual>

    <inertial>
      <origin xyz="0.12475 -0.05716 0.02979" rpy="0 0 0"/>
      <!--<origin xyz="-0.07025 0.00034 -0.00021" rpy="0 0 0"/>-->
      <mass value="1.15977"/>
      <!-- <mass value="0.001"/> -->
      <inertia ixx="1.0" ixy="0.0" ixz="0.0" iyy="1.0" iyz="0.0" izz="1.0" />
      <!--<inertia ixx="0.00096726" ixy="0.00004383" ixz="-0.00002771" iyy="0.00318801" iyz="0.00000627" izz="0.00341484" />-->
    </inertial>
  </link>

  <!-- Joint 4 -->
  <joint name="joint_arm4" type="revolute">
    <parent link="link_arm4"/>
    <child link="link_arm5"/>
   <origin xyz="0.00 0.00 0.08300" rpy="0 0 0"/>
    <axis xyz="0 1 0"/>
    <limit velocity="6.5" effort="1000" lower="-2.03713" upper="2.13530" />
    <dynamics damping="0.7"/>
  </joint>

  <transmission name="transmission_arm4">
    <type>transmission_interface/SimpleTransmission</type>
    <joint name="joint_arm4">
      <hardwareInterface>hardware_interface/EffortJointInterface</hardwareInterface>
    </joint>
    <actuator name="actuartor_arm4">
      <hardwareInterface>hardware_interface/EffortJointInterface</hardwareInterface>
      <mechanicalReduction>1</mechanicalReduction>
    </actuator>
  </transmission>

  <!-- link 5 -->
  <link name="link_arm5">
    <collision>
      <origin xyz="0 -0.048 -0.28890" rpy="0 0 0"/>
      <geometry>
        <mesh filename="package://hcr_description/meshes/5.STL" scale="0.001 0.001 0.001"/>
      </geometry>
    </collision>

    <visual>
      <origin xyz="0 -0.048 -0.28890" rpy="0 0 0"/>
      <geometry>
        <mesh filename="package://hcr_description/meshes/5.STL" scale="0.001 0.001 0.001"/>
      </geometry>
      <material name="grey"/>
    </visual>

    <inertial>
      <origin xyz="0.05642 -0.00217 0.00002" rpy="0 0 0"/>
      <!--<origin xyz="-0.00658 -0.04717 0.00002" rpy="0 0 0"/>-->
      <mass value="0.44688"/>
      <!-- <mass value="0.001"/> -->
      <inertia ixx="1.0" ixy="0.0" ixz="0.0" iyy="1.0" iyz="0.0" izz="1.0" />
      <!--<inertia ixx="0.00030285" ixy="0.00000761" ixz="0.00000031" iyy="0.00022339" iyz="-0.00000001" izz="0.00039766" />-->
    </inertial>
  </link>

  <!-- Joint 5 -->
  <joint name="joint_arm5" type="revolute">
    <parent link="link_arm5"/>
    <child link="link_arm6"/>
    <origin xyz="0.000 0.01785 0.06775" rpy="0 0 0"/>
    <axis xyz="0 0 1"/>
    <limit velocity="6.5" effort="1000" lower="${-pi}" upper="${pi}" />
    <dynamics damping="0.7"/>
  </joint>

  <transmission name="transmission_arm5">
    <type>transmission_interface/SimpleTransmission</type>
    <joint name="joint_arm5">
      <hardwareInterface>hardware_interface/EffortJointInterface</hardwareInterface>
    </joint>
    <actuator name="actuartor_arm5">
      <hardwareInterface>hardware_interface/EffortJointInterface</hardwareInterface>
      <mechanicalReduction>1</mechanicalReduction>
    </actuator>
  </transmission>

  <!-- link 6 -->
  <link name="link_arm6">
    <collision>
      <origin xyz="0 -0.063006 -0.35695008" rpy="0 0 0"/>
      <geometry>
        <mesh filename="package://hcr_description/meshes/6.STL" scale="0.001 0.001 0.001"/>
      </geometry>
    </collision>

    <visual>
      <origin xyz="0 -0.063006 -0.35695008" rpy="0 0 0"/>
      <geometry>
        <mesh filename="package://hcr_description/meshes/6.STL" scale="0.001 0.001 0.001"/>
      </geometry>
      <material name="grey"/>
    </visual>

    <inertial>
      <origin xyz="0.06831 -0.04457 0.00000" rpy="0 0 0"/>
      <!--<origin xyz="-0.05469 0.00043 0.00000" rpy="0 0 0"/>-->
      <mass value="0.43273"/>
      <!-- <mass value="0.001"/> -->
      <inertia ixx="1.0" ixy="0.0" ixz="0.0" iyy="1.0" iyz="0.0" izz="1.0" />
      <!--<inertia ixx="0.00021512" ixy="0.00001009" ixz="0.00000000" iyy="0.00042827" iyz="0.00000000" izz="0.00051436" />-->
    </inertial>
  </link>

  <!-- Joint 6 -->
  <joint name="joint_arm6" type="revolute">
    <parent link="link_arm6"/>
    <child link="link_armEndEff"/>
    <origin xyz="0.00 -0.0207 0.02400" rpy="0 0 0"/>
    <axis xyz="1 0 0"/>
    <limit velocity="6.5" effort="1000" lower="${-pi*0.15}" upper="${pi*0.4}" />
    <!-- <limit velocity="6.5" effort="1000" lower="0.23317" upper="2.74889" /> -->
    <dynamics damping="0.7"/>
  </joint>

  <transmission name="transmission_arm6">
    <type>transmission_interface/SimpleTransmission</type>
    <joint name="joint_arm6">
      <hardwareInterface>hardware_interface/EffortJointInterface</hardwareInterface>
    </joint>
    <actuator name="actuartor_arm6">
      <hardwareInterface>hardware_interface/EffortJointInterface</hardwareInterface>
      <mechanicalReduction>1</mechanicalReduction>
    </actuator>
  </transmission>

  <!-- end link -->
  <link name="link_armEndEff">
    <collision>
      <origin xyz="0 -0.0418 -0.380" rpy="0 0 0"/>
      <geometry>
        <mesh filename="package://hcr_description/meshes/7.STL" scale="0.001 0.001 0.001"/>
      </geometry>
    </collision>

    <visual>
      <origin xyz="0 -0.0418 -0.380" rpy="0 0 0"/>
      <geometry>
        <mesh filename="package://hcr_description/meshes/7.STL" scale="0.001 0.001 0.001"/>
      </geometry>
      <material name="grey"/>
    </visual>

    <inertial>
      <origin xyz="0.00337 0.00000 0.00000" rpy="0 0 0"/>
      <mass value="0.01919"/>
      <inertia ixx="1.0" ixy="0.0" ixz="0.0" iyy="1.0" iyz="0.0" izz="1.0" />
      <!--<inertia ixx="0.00000938" ixy="0.0" ixz="0.0" iyy="0.00000338" iyz="0.0" izz="0.00000635" />-->
    </inertial>
  </link>

</robot>
